{
 "cells": [
  {
   "cell_type": "code",
   "execution_count": 2,
   "metadata": {},
   "outputs": [],
   "source": []
  },
  {
   "cell_type": "code",
   "execution_count": 3,
   "metadata": {},
   "outputs": [
    {
     "name": "stderr",
     "output_type": "stream",
     "text": [
      "usage: ipykernel_launcher.py [-h] [-d DATA_PATH] [-te FILE] [-s FILE]\n",
      "                             [-w2v FILE] [-t2v FILE] [-l FILE]\n",
      "                             [--save_w2v SAVE_W2V] [--save_t2v SAVE_T2V]\n",
      "                             [--export_code_vectors] [--release] [--predict]\n",
      "                             [-fw {keras,tensorflow}] [-v VERBOSE_MODE]\n",
      "                             [-lp FILE] [-tb]\n",
      "ipykernel_launcher.py: error: argument -fw/--framework: invalid choice: '/home/worker/.local/share/jupyter/runtime/kernel-9d77e442-226b-4572-a248-5cfb2074ed81.json' (choose from 'keras', 'tensorflow')\n",
      "ERROR:root:Internal Python error in the inspect module.\n",
      "Below is the traceback from this internal error.\n",
      "\n"
     ]
    },
    {
     "name": "stdout",
     "output_type": "stream",
     "text": [
      "Traceback (most recent call last):\n",
      "  File \"/home/worker/.conda/envs/env/lib/python3.7/argparse.py\", line 1787, in parse_known_args\n",
      "    namespace, args = self._parse_known_args(args, namespace)\n",
      "  File \"/home/worker/.conda/envs/env/lib/python3.7/argparse.py\", line 1993, in _parse_known_args\n",
      "    start_index = consume_optional(start_index)\n",
      "  File \"/home/worker/.conda/envs/env/lib/python3.7/argparse.py\", line 1933, in consume_optional\n",
      "    take_action(action, args, option_string)\n",
      "  File \"/home/worker/.conda/envs/env/lib/python3.7/argparse.py\", line 1845, in take_action\n",
      "    argument_values = self._get_values(action, argument_strings)\n",
      "  File \"/home/worker/.conda/envs/env/lib/python3.7/argparse.py\", line 2377, in _get_values\n",
      "    self._check_value(action, value)\n",
      "  File \"/home/worker/.conda/envs/env/lib/python3.7/argparse.py\", line 2433, in _check_value\n",
      "    raise ArgumentError(action, msg % args)\n",
      "argparse.ArgumentError: argument -fw/--framework: invalid choice: '/home/worker/.local/share/jupyter/runtime/kernel-9d77e442-226b-4572-a248-5cfb2074ed81.json' (choose from 'keras', 'tensorflow')\n",
      "\n",
      "During handling of the above exception, another exception occurred:\n",
      "\n",
      "Traceback (most recent call last):\n",
      "  File \"/home/worker/.conda/envs/env/lib/python3.7/site-packages/IPython/core/interactiveshell.py\", line 3331, in run_code\n",
      "    exec(code_obj, self.user_global_ns, self.user_ns)\n",
      "  File \"<ipython-input-3-9045044a37a6>\", line 1, in <module>\n",
      "    config = Config(set_defaults=True, load_from_args=True, verify=True)\n",
      "  File \"/home/worker/persistent/code/KERN/mlse/code2vec-master/config.py\", line 139, in __init__\n",
      "    self.load_from_args()\n",
      "  File \"/home/worker/persistent/code/KERN/mlse/code2vec-master/config.py\", line 73, in load_from_args\n",
      "    args = self.arguments_parser().parse_args()\n",
      "  File \"/home/worker/.conda/envs/env/lib/python3.7/argparse.py\", line 1755, in parse_args\n",
      "    args, argv = self.parse_known_args(args, namespace)\n",
      "  File \"/home/worker/.conda/envs/env/lib/python3.7/argparse.py\", line 1794, in parse_known_args\n",
      "    self.error(str(err))\n",
      "  File \"/home/worker/.conda/envs/env/lib/python3.7/argparse.py\", line 2508, in error\n",
      "    self.exit(2, _('%(prog)s: error: %(message)s\\n') % args)\n",
      "  File \"/home/worker/.conda/envs/env/lib/python3.7/argparse.py\", line 2495, in exit\n",
      "    _sys.exit(status)\n",
      "SystemExit: 2\n",
      "\n",
      "During handling of the above exception, another exception occurred:\n",
      "\n",
      "Traceback (most recent call last):\n",
      "  File \"/home/worker/.conda/envs/env/lib/python3.7/site-packages/IPython/core/ultratb.py\", line 1148, in get_records\n",
      "    return _fixed_getinnerframes(etb, number_of_lines_of_context, tb_offset)\n",
      "  File \"/home/worker/.conda/envs/env/lib/python3.7/site-packages/IPython/core/ultratb.py\", line 316, in wrapped\n",
      "    return f(*args, **kwargs)\n",
      "  File \"/home/worker/.conda/envs/env/lib/python3.7/site-packages/IPython/core/ultratb.py\", line 350, in _fixed_getinnerframes\n",
      "    records = fix_frame_records_filenames(inspect.getinnerframes(etb, context))\n",
      "  File \"/home/worker/.conda/envs/env/lib/python3.7/inspect.py\", line 1502, in getinnerframes\n",
      "    frameinfo = (tb.tb_frame,) + getframeinfo(tb, context)\n",
      "AttributeError: 'tuple' object has no attribute 'tb_frame'\n"
     ]
    },
    {
     "ename": "SystemExit",
     "evalue": "2",
     "output_type": "error",
     "traceback": [
      "An exception has occurred, use %tb to see the full traceback.\n",
      "\u001b[0;31m---------------------------------------------------------------------------\u001b[0m",
      "\nDuring handling of the above exception, another exception occurred:\n",
      "\u001b[0;31mSystemExit\u001b[0m\u001b[0;31m:\u001b[0m 2\n"
     ]
    },
    {
     "name": "stderr",
     "output_type": "stream",
     "text": [
      "/home/worker/.conda/envs/env/lib/python3.7/site-packages/IPython/core/interactiveshell.py:3339: UserWarning: To exit: use 'exit', 'quit', or Ctrl-D.\n",
      "  warn(\"To exit: use 'exit', 'quit', or Ctrl-D.\", stacklevel=1)\n"
     ]
    }
   ],
   "source": []
  },
  {
   "cell_type": "code",
   "execution_count": 1,
   "metadata": {},
   "outputs": [
    {
     "ename": "NameError",
     "evalue": "name 'dir_types' is not defined",
     "output_type": "error",
     "traceback": [
      "\u001b[0;31m---------------------------------------------------------------------------\u001b[0m",
      "\u001b[0;31mNameError\u001b[0m                                 Traceback (most recent call last)",
      "\u001b[0;32m<ipython-input-1-375cd1d5bba0>\u001b[0m in \u001b[0;36m<module>\u001b[0;34m\u001b[0m\n\u001b[1;32m      8\u001b[0m         \u001b[0;32mbreak\u001b[0m\u001b[0;34m\u001b[0m\u001b[0;34m\u001b[0m\u001b[0m\n\u001b[1;32m      9\u001b[0m \u001b[0;34m\u001b[0m\u001b[0m\n\u001b[0;32m---> 10\u001b[0;31m \u001b[0;32mfor\u001b[0m \u001b[0mdir_type\u001b[0m \u001b[0;32min\u001b[0m \u001b[0mdir_types\u001b[0m\u001b[0;34m:\u001b[0m\u001b[0;34m\u001b[0m\u001b[0;34m\u001b[0m\u001b[0m\n\u001b[0m\u001b[1;32m     11\u001b[0m     \u001b[0mget_lines2predict\u001b[0m\u001b[0;34m(\u001b[0m\u001b[0mDATASET_PATH\u001b[0m \u001b[0;34m/\u001b[0m \u001b[0mdir_type\u001b[0m\u001b[0;34m)\u001b[0m\u001b[0;34m\u001b[0m\u001b[0;34m\u001b[0m\u001b[0m\n\u001b[1;32m     12\u001b[0m     \u001b[0;32mbreak\u001b[0m\u001b[0;34m\u001b[0m\u001b[0;34m\u001b[0m\u001b[0m\n",
      "\u001b[0;31mNameError\u001b[0m: name 'dir_types' is not defined"
     ]
    }
   ],
   "source": []
  },
  {
   "cell_type": "code",
   "execution_count": null,
   "metadata": {},
   "outputs": [],
   "source": []
  }
 ],
 "metadata": {
  "kernelspec": {
   "display_name": "Python 3",
   "language": "python",
   "name": "python3"
  },
  "language_info": {
   "codemirror_mode": {
    "name": "ipython",
    "version": 3
   },
   "file_extension": ".py",
   "mimetype": "text/x-python",
   "name": "python",
   "nbconvert_exporter": "python",
   "pygments_lexer": "ipython3",
   "version": "3.7.6"
  }
 },
 "nbformat": 4,
 "nbformat_minor": 4
}
